Workbook

Sheet 00_README
B2: Software Opportunity Research Portfolio
B3: Generated 2026-07-11 · 32 opportunities (P01–P32) · Scores editable · Totals & Priority are Excel formulas
B5: How to use
B6: • | C6: 1. Edit only yellow cells with blue font (score inputs 1–5) on 01_Master_Portfolio.
B7: • | C7: 2. TOTAL (column K) and Priority (column L) recalculate automatically—do not hardcode them.
B8: • | C8: 3. Priority bands: NOW ≥ 20 · NEXT 16–19 · LATER 12–15 · PARK < 12 (sum of five scores).
B9: • | C9: 4. Review 02–04 for research, build, and monetization detail per opportunity.
B10: • | C10: 5. Use 05_Scoring_Matrix for visual ranking; 06_Pipeline for phase planning.
B11: • | C11: 6. 07_Market_Context holds macro notes (directional figures with sources).
B12: • | C12: 7. Log new research in 08_Research_Log. Keep CSV export in sync when scores change (re-run generator or copy Master).
B13: • | C13: 8. Conventions: blue font + yellow fill = inputs; black = labels/formulas (financial modeling style).
B14: • | C14: 9. Visibility marker (Master cols M–N): OPEN-CORE = public OSS repo with a paid layer on top; PRIVATE-PAID = closed source, the product itself is paid.
B16: Sheets
B17: • | C17: 00_README — this guide
B18: • | C18: 01_Master_Portfolio — all opportunities, scores, TOTAL formula, Priority formula
B19: • | C19: 02_Deep_Research — market, competitors, risks, evidence, next research
B20: • | C20: 03_Build_Delivery — platforms, MVP, stack, repo, effort
B21: • | C21: 04_Monetization — ICP, pricing, GTM, revenue model
B22: • | C22: 05_Scoring_Matrix — linked scores + color scale + bar chart
B23: • | C23: 06_Pipeline — NOW / NEXT / LATER / PARK phases
B24: • | C24: 07_Market_Context — macro market notes & sources
B25: • | C25: 08_Research_Log — dated research log entries
B27: Scoring dimensions (1–5)
B28: • | C28: Burn — how painful/urgent is the problem for buyers?
B29: • | C29: Software-native — can this be pure software with leverage (not services-heavy)?
B30: • | C30: Ship speed — how fast can a small team ship a credible MVP?
B31: • | C31: Distribution — can you reach users cheaply (npx, communities, PLG)?
B32: • | C32: Moat — defensibility over 2–3 years (data, network, workflow lock-in, brand).
B34: Files
B35: • | C35: Excel: Software_Opportunity_Research_Portfolio.xlsx
B36: • | C36: CSV mirror of Master: Software_Opportunity_Master_Portfolio.csv
B37: • | C37: Index: SOFTWARE_PORTFOLIO_INDEX.md
B38: • | C38: Regenerate: python3 scripts/generate_software_portfolio.py
B40: Working context
B41: • | C41: Shipped on npm: ai-instruct-sync@0.2.0-beta.0 (P01), ai-setup-doctor@0.1.0-beta.0 (P02), @bhaskarauthor/mcp-sync@0.2.0 + mcp-config-sync (P03).
B42: • | C42: Strategic line — AI dev hygiene suite: sync (P01/P03) → diagnose (P02) → secure (P29) → control spend (P30); same audience, same npx flywheel, paid layers on top.
B43: • | C43: Default bias: ship AI CLI tooling NOW; India SMB and heavier SaaS NEXT/LATER; P31 indic-voice-flow is the standalone consumer revenue bet.
B44: • | C44: Figures in Market Context are directional mid-decade estimates—validate before fundraising decks.

Sheet 01_Master_Portfolio
A1: Software Opportunity Master Portfolio
A2: Edit yellow/blue score cells only (F–J). TOTAL = SUM(F:J). Priority = NOW/NEXT/LATER/PARK by TOTAL thresholds. Visibility: OPEN-CORE = public repo + paid layer on top; PRIVATE-PAID = closed source. Sorted recommendation: filter Priority = NOW.
A4: ID | B4: Name | C4: Category | D4: One-liner | E4: Problem | F4: Burn | G4: Software-native | H4: Ship speed | I4: Distribution | J4: Moat | K4: TOTAL | L4: Priority | M4: Visibility | N4: Paid layer | O4: Status | P4: Stage | Q4: Platforms | R4: Repo | S4: Tags | T4: Notes | U4: Last reviewed
A5: P01 | B5: instruct-sync | C5: AI Tooling | D5: Sync AI coding rules/instructions across Cursor, Copilot, Claude, Windsurf, Aider, Gemini, Continue | E5: Every AI coding agent uses different rules files; they drift and teams lose consistency. | F5: 5 | G5: 5 | H5: 5 | I5: 5 | J5: 3 | K5: =F5+G5+H5+I5+J5 | L5: =IF(K5>=20,"NOW",IF(K5>=16,"NEXT",IF(K5>=12,"LATER","PARK"))) | M5: OPEN-CORE | N5: Pro team sync + policy ($8–15/dev/mo) | O5: Public beta | P5: Shipped / iterate | Q5: CLI | R5: instruct-sync | S5: AI,CLI,devtools,rules,sync,suite | T5: npm ai-instruct-sync@0.2.0-beta.0; hygiene suite #1 (sync); primary NOW product | U5: 2026-07-11
A6: P02 | B6: ai-setup-doctor | C6: AI Tooling | D6: Read-only diagnostics for agents, MCP, secrets, Node/project hygiene before AI coding sessions | E6: Broken MCP, leaked secrets in agent configs, bloated rules, and project hygiene waste hours. | F6: 5 | G6: 5 | H6: 5 | I6: 4 | J6: 3 | K6: =F6+G6+H6+I6+J6 | L6: =IF(K6>=20,"NOW",IF(K6>=16,"NEXT",IF(K6>=12,"LATER","PARK"))) | M6: OPEN-CORE | N6: Hosted CI checks tier | O6: Published beta | P6: Shipped / iterate | Q6: CLI | R6: ai-setup-doctor | S6: AI,CLI,diagnostics,MCP,secrets,suite | T6: npm ai-setup-doctor@0.1.0-beta.0 (latest+beta); hygiene suite #2 (diagnose) | U6: 2026-07-11
A7: P03 | B7: mcp-sync | C7: AI Tooling | D7: Canonical MCP server config sync across Cursor, Claude, VS Code, Windsurf clients | E7: MCP server JSON configs diverge per client; env vars and secrets get copy-pasted unsafely. | F7: 4 | G7: 5 | H7: 5 | I7: 4 | J7: 3 | K7: =F7+G7+H7+I7+J7 | L7: =IF(K7>=20,"NOW",IF(K7>=16,"NEXT",IF(K7>=12,"LATER","PARK"))) | M7: OPEN-CORE | N7: Org-wide MCP catalog ($12/seat) | O7: Published | P7: Shipped / iterate | Q7: CLI,API | R7: mcp-sync | S7: AI,MCP,CLI,config,suite | T7: npm mcp-config-sync@0.2.0 + @bhaskarauthor/mcp-sync; hygiene suite #3; co-located at development/mcp-sync (own git remote) | U7: 2026-07-11
A8: P04 | B8: secret-guard | C8: AI Tooling / Security | D8: Pre-commit and CI guard against secrets leaking into AI agent rules, MCP env, and prompts | E8: API keys land in .cursor, CLAUDE.md, MCP env blocks, and chat exports. | F8: 5 | G8: 5 | H8: 4 | I8: 4 | J8: 3 | K8: =F8+G8+H8+I8+J8 | L8: =IF(K8>=20,"NOW",IF(K8>=16,"NEXT",IF(K8>=12,"LATER","PARK"))) | M8: OPEN-CORE | N8: Team dashboard + SARIF CI ($15–40/dev/mo) | O8: Concept | P8: Research | Q8: CLI,Extension,API | R8: secret-guard | S8: security,secrets,AI,CI | T8: Can extract patterns from setup-doctor secret checks | U8: 2026-07-11
A9: P05 | B9: llm-spend | C9: AI Tooling / FinOps | D9: Unified LLM cost, token, and budget observability across OpenAI, Anthropic, Google, Azure, open models | E9: Teams burn LLM budget with zero allocation visibility by project/user/feature. | F9: 5 | G9: 5 | H9: 3 | I9: 3 | J9: 3 | K9: =F9+G9+H9+I9+J9 | L9: =IF(K9>=20,"NOW",IF(K9>=16,"NEXT",IF(K9>=12,"LATER","PARK"))) | M9: PRIVATE-PAID | N9: SaaS usage tiers ($49–299/mo) | O9: Concept | P9: Research | Q9: Web,API,CLI | R9: llm-spend | S9: AI,FinOps,observability,cost | T9: Superseded for NOW by P30 agent-spend-guard (guardrails wedge); keep as broad-platform LATER path | U9: 2026-07-11
A10: P06 | B10: skill-sync | C10: AI Tooling | D10: Package, version, and sync agent skills/tools/prompts like packages across teams | E10: Custom agent skills and prompt packs are copy-pasted Slackware with no versions. | F10: 3 | G10: 5 | H10: 3 | I10: 3 | J10: 4 | K10: =F10+G10+H10+I10+J10 | L10: =IF(K10>=20,"NOW",IF(K10>=16,"NEXT",IF(K10>=12,"LATER","PARK"))) | M10: OPEN-CORE | N10: Private registry ($99+/mo) | O10: Concept | P10: Watch | Q10: CLI,API,Web | R10: skill-sync | S10: AI,skills,registry,devtools | T10: Depends on skills format maturity (Claude skills, custom tools) | U10: 2026-07-11
A11: P07 | B11: shadow-AI | C11: AI Tooling / Security / GRC | D11: Discover unauthorized AI tools, browser extensions, and SaaS usage across the enterprise | E11: Employees paste company data into consumer ChatGPT/Claude without IT visibility. | F11: 5 | G11: 4 | H11: 2 | I11: 2 | J11: 3 | K11: =F11+G11+H11+I11+J11 | L11: =IF(K11>=20,"NOW",IF(K11>=16,"NEXT",IF(K11>=12,"LATER","PARK"))) | M11: PRIVATE-PAID | N11: Enterprise per-seat SaaS | O11: Concept | P11: Research | Q11: Web,Extension,API | R11: shadow-ai | S11: security,GRC,CASB,AI | T11: Enterprise sales motion; not indie-friendly | U11: 2026-07-11
A12: P08 | B12: eval-harness | C12: AI Tooling | D12: Lightweight eval harness for prompt/agent regression tests in CI for product teams | E12: Prompt changes break behavior silently; full ML platforms are overkill for app teams. | F12: 4 | G12: 5 | H12: 3 | I12: 3 | J12: 3 | K12: =F12+G12+H12+I12+J12 | L12: =IF(K12>=20,"NOW",IF(K12>=16,"NEXT",IF(K12>=12,"LATER","PARK"))) | M12: OPEN-CORE | N12: Cloud runs ($29–199/mo) | O12: Concept | P12: Research | Q12: CLI,API,Web | R12: eval-harness | S12: AI,eval,testing,CI | T12: Compete on simplicity vs LangSmith/Promptfoo | U12: 2026-07-11
A13: P09 | B13: auth-anomaly-radar | C13: Security / Identity / Fraud | D13: Lightweight auth anomaly detection for SaaS (impossible travel, credential stuffing signals) | E13: SMBs enable Auth0/Cognito but lack fraud signals without enterprise SIEM. | F13: 4 | G13: 5 | H13: 3 | I13: 2 | J13: 3 | K13: =F13+G13+H13+I13+J13 | L13: =IF(K13>=20,"NOW",IF(K13>=16,"NEXT",IF(K13>=12,"LATER","PARK"))) | M13: PRIVATE-PAID | N13: MAU-based SaaS | O13: Concept | P13: Research | Q13: API,Web | R13: auth-anomaly-radar | S13: security,identity,fraud,SaaS | T13: Integrate as webhook consumer for auth providers | U13: 2026-07-11
A14: P10 | B14: fraud-signal-kit | C14: Security / Identity / Fraud | D14: Composable fraud signal APIs (device, velocity, email risk) for Indian fintech and marketplaces | E14: India digital payments fraud needs local signal stacks cheaper than global suites. | F14: 4 | G14: 4 | H14: 2 | I14: 2 | J14: 3 | K14: =F14+G14+H14+I14+J14 | L14: =IF(K14>=20,"NOW",IF(K14>=16,"NEXT",IF(K14>=12,"LATER","PARK"))) | M14: PRIVATE-PAID | N14: Usage-priced API | O14: Concept | P14: Watch | Q14: API | R14: fraud-signal-kit | S14: fraud,fintech,India,API | T14: Regulatory/compliance heavy; partner path | U14: 2026-07-11
A15: P11 | B15: cloud-waste-radar | C15: Cloud FinOps | D15: Find idle cloud resources and rightsizing opportunities for AWS/GCP/Azure startups | E15: Surveys classically cite ~30% cloud waste; startups overprovision without FinOps staff. | F15: 4 | G15: 5 | H15: 3 | I15: 3 | J15: 2 | K15: =F15+G15+H15+I15+J15 | L15: =IF(K15>=20,"NOW",IF(K15>=16,"NEXT",IF(K15>=12,"LATER","PARK"))) | M15: PRIVATE-PAID | N15: SaaS + savings share | O15: Concept | P15: Research | Q15: Web,CLI,API | R15: cloud-waste-radar | S15: FinOps,cloud,AWS,cost | T15: Crowded but SMB pricing gap exists | U15: 2026-07-11
A16: P12 | B16: dev-onboard-os | C16: Dev Productivity | D16: Opinionated new-hire engineering onboarding OS: env, access, docs, first PR in days not weeks | E16: Onboarding still tribal; new engineers lose 2–4 weeks to setup and tribal knowledge. | F16: 3 | G16: 4 | H16: 3 | I16: 3 | J16: 2 | K16: =F16+G16+H16+I16+J16 | L16: =IF(K16>=20,"NOW",IF(K16>=16,"NEXT",IF(K16>=12,"LATER","PARK"))) | M16: PRIVATE-PAID | N16: Seat SaaS | O16: Concept | P16: Watch | Q16: Web,CLI | R16: dev-onboard-os | S16: onboarding,devtools,productivity | T16: Overlaps DX platforms; hard differentiation | U16: 2026-07-11
... A36: P32 | B36: pr-triage | C36: Dev Productivity / Quality | D36: Risk-rank AI-generated PR diffs so humans review the 20% that actually matters | E36: Developers now spend 11.4 hrs/week reviewing AI code vs 9.8 writing; 66% cite 'almost right, but not quite' as top frustration. | F36: 5 | G36: 5 | H36: 3 | I36: 3 | J36: 2 | K36: =F36+G36+H36+I36+J36 | L36: =IF(K36>=20,"NOW",IF(K36>=16,"NEXT",IF(K36>=12,"LATER","PARK"))) | M36: OPEN-CORE | N36: Org tier ($99+/mo) | O36: Concept | P36: Watch | Q36: CLI,API,Extension | R36: pr-triage | S36: AI,code-review,CI,devtools | T36: Big pain but CodeRabbit/Greptile/GitHub converging; watch for a hunk-level triage wedge | U36: 2026-07-11
A38: Legend
A39: Input scores | B39: Yellow fill + blue font = editable (1–5)
A40: TOTAL / Priority | B40: Excel formulas — do not overwrite
A41: NOW | B41: TOTAL ≥ 20
A42: NEXT | B42: TOTAL 16–19
A43: LATER | B43: TOTAL 12–15
A44: PARK | B44: TOTAL < 12
A45: OPEN-CORE | B45: Goes public (OSS repo); monetize via paid layer on top
A46: PRIVATE-PAID | B46: Stays private (closed source); the product itself is paid

Sheet 02_Deep_Research
A1: Deep Research Briefs
A2: Detailed research notes per opportunity. Score columns link to Master where noted; narrative is curated.
A4: ID | B4: Name | C4: Category | D4: Market context | E4: Competitors / alternatives | F4: Why now | G4: Risks | H4: Evidence / traction signals | I4: Next research questions | J4: Burn | K4: Software-native | L4: Ship | M4: Dist | N4: Moat | O4: TOTAL (link)
A5: P01 | B5: instruct-sync | C5: AI Tooling | D5: AI coding assistants exploding; multi-agent workplaces common. Rules/context fragmentation is daily pain. | E5: rulesync, personal scripts, agent-specific converters, Cursor project rules only | F5: Agent sprawl (Cursor+Copilot+Claude Code etc.) peaking; OSS CLI distribution via npx is proven. | G5: Agents change file formats; big vendors ship native sync; commodity CLI risk | H5: Live beta, multi-agent adapters, dry-run/backup UX; HN/Reddit-ready narrative | I5: Download retention, paid team features demand, enterprise rules governance | J5: 5 | K5: 5 | L5: 5 | M5: 5 | N5: 3 | O5: ='01_Master_Portfolio'!K5
A6: P02 | B6: ai-setup-doctor | C6: AI Tooling | D6: Same AI-dev tool wave; diagnostic CLIs (doctor pattern) have high shareability. | E6: Ad-hoc scripts, security scanners (generic), MCP inspector tools | F6: MCP+multi-agent setup pain is acute; doctor UX is viral (npx check). | G6: Overlap with secret-guard / instruct-sync; needs clear product boundary | H6: Fixtures for bad MCP, secrets, drift, bloat already in repo | I6: Which checks users value most; CI integration demand | J6: 5 | K6: 5 | L6: 5 | M6: 4 | N6: 3 | O6: ='01_Master_Portfolio'!K6
A7: P03 | B7: mcp-sync | C7: AI Tooling | D7: MCP becoming standard transport for agent tools; multi-client users growing fast. | E7: Manual JSON, vendor UI only, early MCP managers | F7: MCP ecosystem still immature; window for open standard tooling. | G7: Spec churn; official multi-client managers from Anthropic/OpenAI/MS | H7: Same distribution motion as instruct-sync; shared adapter patterns | I7: Map all client MCP file locations & schema diffs | J7: 4 | K7: 5 | L7: 5 | M7: 4 | N7: 3 | O7: ='01_Master_Portfolio'!K7
A8: P04 | B8: secret-guard | C8: AI Tooling / Security | D8: Secrets sprawl + AI configs = new leak surface; security budgets growing. | E8: gitleaks, trufflehog, GitHub secret scanning (not AI-path aware) | F8: AI config files are new secret vectors poorly covered by classic scanners. | G8: Crowded secrets market; need AI-path differentiation | H8: setup-doctor leaky-secrets fixtures; enterprise pain stories | I8: False positive rates; VS Code extension demand | J8: 5 | K8: 5 | L8: 4 | M8: 4 | N8: 3 | O8: ='01_Master_Portfolio'!K8
A9: P05 | B9: llm-spend | C9: AI Tooling / FinOps | D9: LLM spend becoming material OpEx; CFOs ask for unit economics of AI features. | E9: Helicone, Langfuse, Portkey, vendor dashboards, CloudZero AI modules | F9: Multi-provider reality; startups need budget caps before Series A burns. | G9: Crowded observability; need SMB wedge or India/SME pricing | H9: Surveys of runaway GPT bills; proxy open-source traction | I9: Willingness to pay SMB vs enterprise; proxy vs pull-billing UX | J9: 5 | K9: 5 | L9: 3 | M9: 3 | N9: 3 | O9: ='01_Master_Portfolio'!K9
A10: P06 | B10: skill-sync | C10: AI Tooling | D10: Agent skills emerging as unit of reuse; registries will form. | E10: Internal wikis, prompt marketplaces, LangChain hubs | F10: Early—format still fluid; park until standards stabilize slightly. | G10: Premature; vendors lock skills into their ecosystems | H10: Analogous to npm for agent capabilities narrative | I10: Track Claude/Cursor skill formats quarterly | J10: 3 | K10: 5 | L10: 3 | M10: 3 | N10: 4 | O10: ='01_Master_Portfolio'!K10
A11: P07 | B11: shadow-AI | C11: AI Tooling / Security / GRC | D11: Shadow IT + GenAI = board-level risk; CASB/SSPM vendors expanding. | E11: Netskope, Zscaler, Microsoft Purview, specialized AI governance startups | F11: Regulators and CISOs waking up; budgets exist but sales cycles long. | G11: Enterprise sales, privacy, needs endpoint/network hooks | H11: Gartner-style AI governance category forming | I11: SMB browser-extension wedge vs full CASB | J11: 5 | K11: 4 | L11: 2 | M11: 2 | N11: 3 | O11: ='01_Master_Portfolio'!K11
A12: P08 | B12: eval-harness | C12: AI Tooling | D12: Eval tooling category heating; every serious AI product needs regression. | E12: Promptfoo, LangSmith, Braintrust, DeepEval, custom pytest | F12: Agent apps in production need CI; many teams still ad-hoc. | G12: Crowded; hard to differentiate without unique datasets or UX | H12: Promptfoo OSS traction proves demand | I12: Niche: India cost-sensitive or agent-trace specific | J12: 4 | K12: 5 | L12: 3 | M12: 3 | N12: 3 | O12: ='01_Master_Portfolio'!K12
A13: P09 | B13: auth-anomaly-radar | C13: Security / Identity / Fraud | D13: Identity attacks rising; mid-market cannot afford full fraud stacks. | E13: Arkose, Sift, Fingerprint, Auth0 Attack Protection, Cloudflare | F13: Credential stuffing commoditized; need affordable SMB layer. | G13: Incumbents bundle features; false positives hurt UX | H13: Auth provider event APIs enable third-party detection | I13: WTP for $99–499/mo vs free Auth0 features | J13: 4 | K13: 5 | L13: 3 | M13: 2 | N13: 3 | O13: ='01_Master_Portfolio'!K13
A14: P10 | B14: fraud-signal-kit | C14: Security / Identity / Fraud | D14: India UPI/e-com fraud scale; local players + banks buying signals. | E14: Signzy, Bureau, TransUnion, global Device Intelligence | F14: Digital public infrastructure + fintech boom, but hard regulated moat. | G14: Data partnerships, capital, regulation | H14: India fintech security spend growing with volume | I14: Partnership with KYC vendors; niche vertical (BNPL, gaming) | J14: 4 | K14: 4 | L14: 2 | M14: 2 | N14: 3 | O14: ='01_Master_Portfolio'!K14
A15: P11 | B15: cloud-waste-radar | C15: Cloud FinOps | D15: Cloud FinOps large; waste ~30% class from industry surveys (Flexera et al.). | E15: Vantage, CloudHealth, Kubecost, native AWS Cost Explorer, nOps | F15: Interest rates / efficiency culture; AI infra spend spike. | G15: Commoditization; AWS native improvements | H15: Always-on demand for idle EBS/EIP/RDS detection | I15: India price-sensitive wedge; agentic auto-remediation angle | J15: 4 | K15: 5 | L15: 3 | M15: 3 | N15: 2 | O15: ='01_Master_Portfolio'!K15
A16: P12 | B16: dev-onboard-os | C16: Dev Productivity | D16: DevEx budgets rising; remote/hybrid makes onboarding harder. | E16: Compass, Internal.io, Notion templates, custom scripts | F16: AI can personalize onboarding paths; still crowded. | G16: Low willingness to pay; internal tools suffice | H16: DX surveys show onboarding as top pain | I16: Vertical: AI-era onboarding (agents + secrets + MCP day-1) | J16: 3 | K16: 4 | L16: 3 | M16: 3 | N16: 2 | O16: ='01_Master_Portfolio'!K16
... A36: P32 | B36: pr-triage | C36: Dev Productivity / Quality | D36: Review burden reversed the 2024 pattern; trust in AI output fell to 29% — triage is the bottleneck, not generation. | E36: CodeRabbit, Greptile, GitHub Copilot code review, Graphite — all full reviewers, none pure triage | F36: Review fatigue is a top-3 2026 developer pain and still underserved as a ranking (not reviewing) problem. | G36: Well-funded incumbents add triage as a feature; thin moat | H36: 2026 dev pain surveys (11.4h review, 75% more logic errors in AI PRs) | I36: Hunk-level risk scoring accuracy; whether teams want ranking vs another reviewer | J36: 5 | K36: 5 | L36: 3 | M36: 3 | N36: 2 | O36: ='01_Master_Portfolio'!K36

Sheet 03_Build_Delivery
A1: Build & Delivery Matrix
A2: Platform flags derived from opportunity design. MVP and stack are starting recommendations.
A4: ID | B4: Name | C4: CLI | D4: Web | E4: Android | F4: iOS | G4: Desktop | H4: API | I4: Extension | J4: MVP scope | K4: Suggested stack | L4: Repo name | M4: Est. weeks | N4: Delivery notes | O4: Platforms (summary)
A5: P01 | B5: instruct-sync | C5: Y | D5: — | E5: — | F5: — | G5: — | H5: — | I5: — | J5: status/diff/sync/validate/init across 7+ agents; dry-run default; --json | K5: TypeScript, Node 20+, zero runtime deps, vitest | L5: instruct-sync | M5: 2 | N5: Already shipping; focus on agents, lint, team mode | O5: CLI
A6: P02 | B6: ai-setup-doctor | C6: Y | D6: — | E6: — | F6: — | G6: — | H6: — | I6: — | J6: check (default), --json, --strict, --cwd; core agent/MCP/secret checks | K6: TypeScript, Node, CLI | L6: ai-setup-doctor | M6: 1 | N6: Publish to npm; couple with instruct-sync funnel | O6: CLI
A7: P03 | B7: mcp-sync | C7: Y | D7: — | E7: — | F7: — | G7: — | H7: Y | I7: — | J7: status/diff/sync for 4 clients; secret redaction; dry-run | K7: TypeScript CLI; shared libs with instruct-sync | L7: mcp-sync | M7: 3 | N7: Shipped; grow adoption alongside instruct-sync funnel | O7: CLI,API
A8: P04 | B8: secret-guard | C8: Y | D8: — | E8: — | F8: — | G8: — | H8: Y | I8: Y | J8: Scan agent dirs + MCP JSON; pre-commit hook; SARIF output | K8: Go or Rust scanner core + TS wrapper; or pure TS | L8: secret-guard | M8: 4 | N8: Start as setup-doctor module; split when traction | O8: CLI,Extension,API
A9: P05 | B9: llm-spend | C9: Y | D9: Y | E9: — | F9: — | G9: — | H9: Y | I9: — | J9: Proxy + per-key budgets + simple dashboard + alerts | K9: TS (Hono/Fastify), Postgres, React, provider SDKs | L9: llm-spend | M9: 8 | N9: Larger surface; not NOW unless paid design partner | O9: Web,API,CLI
A10: P06 | B10: skill-sync | C10: Y | D10: Y | E10: — | F10: — | G10: — | H10: Y | I10: — | J10: Skill package schema + install/publish CLI + private registry | K10: TS CLI + simple registry (S3 + metadata DB) | L10: skill-sync | M10: 10 | N10: LATER after instruct/mcp patterns proven | O10: CLI,API,Web
A11: P07 | B11: shadow-AI | C11: — | D11: Y | E11: — | F11: — | G11: — | H11: Y | I11: Y | J11: Browser extension + domain allowlist + admin dashboard (pilot) | K11: Chrome ext, Node API, React admin | L11: shadow-ai | M11: 12 | N11: PARK for solo; partner or later | O11: Web,Extension,API
A12: P08 | B12: eval-harness | C12: Y | D12: Y | E12: — | F12: — | G12: — | H12: Y | I12: — | J12: YAML cases, multi-provider run, score thresholds, GitHub Action | K12: Python or TS CLI + optional dashboard | L12: eval-harness | M12: 6 | N12: NEXT if design partner; else watch | O12: CLI,API,Web
A13: P09 | B13: auth-anomaly-radar | C13: — | D13: Y | E13: — | F13: — | G13: — | H13: Y | I13: — | J13: Ingest login events → risk score → Slack/webhook | K13: Python/Go service, Postgres, React | L13: auth-anomaly-radar | M13: 10 | N13: LATER; needs trust + data | O13: API,Web
A14: P10 | B14: fraud-signal-kit | C14: — | D14: — | E14: — | F14: — | G14: — | H14: Y | I14: — | J14: 3 signals (email, velocity, device fingerprint lite) + sandbox | K14: Go API, Redis, Postgres | L14: fraud-signal-kit | M14: 16 | N14: PARK solo without partners | O14: API
A15: P11 | B15: cloud-waste-radar | C15: Y | D15: Y | E15: — | F15: — | G15: — | H15: Y | I15: — | J15: AWS read-only connector + idle resource report + Slack digest | K15: Python, AWS SDK, Next.js | L15: cloud-waste-radar | M15: 8 | N15: LATER unless clear niche | O15: Web,CLI,API
A16: P12 | B16: dev-onboard-os | C16: Y | D16: Y | E16: — | F16: — | G16: — | H16: — | I16: — | J16: Checklist product + golden path CLI + progress for managers | K16: Next.js, Postgres, integrations (GitHub, Slack) | L16: dev-onboard-os | M16: 10 | N16: Tie to setup-doctor for AI-era wedge later | O16: Web,CLI
... A36: P32 | B36: pr-triage | C36: Y | D36: — | E36: — | F36: — | G36: — | H36: Y | I36: Y | J36: CLI + GitHub Action: rank hunks by blast radius, coverage gaps, AI-origin heuristics | K36: TypeScript + AST diff analysis; optional LLM assist | L36: pr-triage | M36: 6 | N36: Watch; build only if P29/P30 traction frees capacity | O36: CLI,API,Extension

Sheet 04_Monetization
A1: Monetization & GTM
A2: ICP, pricing, and go-to-market per opportunity. Priority/TOTAL linked to Master.
A4: ID | B4: Name | C4: Category | D4: ICP | E4: Pricing hypothesis | F4: GTM motion | G4: Revenue model | H4: ARPU hint | I4: Priority (link) | J4: TOTAL (link)
A5: P01 | B5: instruct-sync | C5: AI Tooling | D5: Indie/pro AI-assisted developers; later eng leads at multi-agent shops | E5: OSS free; optional Pro team sync + policy ($8–15/dev/mo later) | F5: npx, Show HN, r/cursor, X, npm, directories, compare posts | G5: Open core → team SaaS | H5: $0 OSS; $10–20/seat Pro (est.) | I5: ='01_Master_Portfolio'!L5 | J5: ='01_Master_Portfolio'!K5
A6: P02 | B6: ai-setup-doctor | C6: AI Tooling | D6: AI coding developers setting up new machines/repos | E6: OSS free; CI cloud later | F6: Bundle mention in instruct-sync README; Twitter demos of red/green checks | G6: OSS + optional hosted CI | H6: $0–$20/mo CI tier | I6: ='01_Master_Portfolio'!L6 | J6: ='01_Master_Portfolio'!K6
A7: P03 | B7: mcp-sync | C7: AI Tooling | D7: Power users of MCP across multiple IDEs | E7: OSS; Pro for org-wide MCP catalogs | F7: MCP community, Discord, HN, couple with instruct-sync | G7: Open core | H7: $12/seat org catalog | I7: ='01_Master_Portfolio'!L7 | J7: ='01_Master_Portfolio'!K7
A8: P04 | B8: secret-guard | C8: AI Tooling / Security | D8: Security-conscious teams using AI coding tools | E8: OSS CLI; team dashboard $15–40/dev/mo | F8: Security Twitter, DevSecOps blogs, GitHub Action marketplace | G8: Open core SaaS | H8: $25/seat team | I8: ='01_Master_Portfolio'!L8 | J8: ='01_Master_Portfolio'!K8
A9: P05 | B9: llm-spend | C9: AI Tooling / FinOps | D9: Startups with multi-LLM apps; AI platform teams | E9: Free tier; $49–299/mo by volume | F9: Product Hunt, AI eng communities, content on unit cost | G9: SaaS usage tiers | H9: $99/mo mid | I9: ='01_Master_Portfolio'!L9 | J9: ='01_Master_Portfolio'!K9
A10: P06 | B10: skill-sync | C10: AI Tooling | D10: Platform teams standardizing agent capabilities | E10: Free public; private registry $99+/mo | F10: DevRel, skill examples, partner agents | G10: Registry SaaS | H10: $150/mo org | I10: ='01_Master_Portfolio'!L10 | J10: ='01_Master_Portfolio'!K10
A11: P07 | B11: shadow-AI | C11: AI Tooling / Security / GRC | D11: CISOs at mid-market / regulated industries | E11: Per seat $5–15/mo enterprise | F11: Security conferences, MSSP partners, content on data leakage | G11: Enterprise SaaS | H11: $8/seat | I11: ='01_Master_Portfolio'!L11 | J11: ='01_Master_Portfolio'!K11
A12: P08 | B12: eval-harness | C12: AI Tooling | D12: Product engineers shipping LLM features | E12: OSS; cloud runs $29–199/mo | F12: GitHub Action + docs SEO + AI eng Discord | G12: Open core SaaS | H12: $79/mo | I12: ='01_Master_Portfolio'!L12 | J12: ='01_Master_Portfolio'!K12
A13: P09 | B13: auth-anomaly-radar | C13: Security / Identity / Fraud | D13: SaaS companies 10–200 eng, India SaaS exporters | E13: MAU-based $99–999/mo | F13: Auth0/Clerk marketplaces, security newsletters | G13: SaaS | H13: $250/mo | I13: ='01_Master_Portfolio'!L13 | J13: ='01_Master_Portfolio'!K13
A14: P10 | B14: fraud-signal-kit | C14: Security / Identity / Fraud | D14: India fintech / marketplace risk teams | E14: Per API call + MRR | F14: Fintech meetups, RBI ecosystem events, founders network | G14: Usage API | H14: Usage-variable | I14: ='01_Master_Portfolio'!L14 | J14: ='01_Master_Portfolio'!K14
A15: P11 | B15: cloud-waste-radar | C15: Cloud FinOps | D15: Startups $5k–50k/mo cloud bill without FinOps hire | E15: % of savings or $99–499/mo | F15: Content on waste, Product Hunt, AWS Marketplace | G15: SaaS + savings share | H15: $199/mo | I15: ='01_Master_Portfolio'!L15 | J15: ='01_Master_Portfolio'!K15
A16: P12 | B16: dev-onboard-os | C16: Dev Productivity | D16: Eng managers at 20–200 person product orgs | E16: $8–15/seat/mo | F16: Eng manager content, GitHub App | G16: SaaS seats | H16: $12/seat | I16: ='01_Master_Portfolio'!L16 | J16: ='01_Master_Portfolio'!K16
... A36: P32 | B36: pr-triage | C36: Dev Productivity / Quality | D36: Teams merging heavy AI-generated code | E36: OSS; org tier $99+/mo | F36: GitHub marketplace, review-fatigue content | G36: Open core | H36: $99/mo | I36: ='01_Master_Portfolio'!L36 | J36: ='01_Master_Portfolio'!K36

Sheet 05_Scoring_Matrix
A1: Scoring Matrix (linked to Master)
A2: All score and TOTAL cells are formulas → 01_Master_Portfolio. Change scores only on Master (or edit Master F–J).
A4: ID | B4: Name | C4: Burn | D4: Software-native | E4: Ship speed | F4: Distribution | G4: Moat | H4: TOTAL | I4: Priority
A5: P01 | B5: instruct-sync | C5: ='01_Master_Portfolio'!F5 | D5: ='01_Master_Portfolio'!G5 | E5: ='01_Master_Portfolio'!H5 | F5: ='01_Master_Portfolio'!I5 | G5: ='01_Master_Portfolio'!J5 | H5: ='01_Master_Portfolio'!K5 | I5: ='01_Master_Portfolio'!L5
A6: P02 | B6: ai-setup-doctor | C6: ='01_Master_Portfolio'!F6 | D6: ='01_Master_Portfolio'!G6 | E6: ='01_Master_Portfolio'!H6 | F6: ='01_Master_Portfolio'!I6 | G6: ='01_Master_Portfolio'!J6 | H6: ='01_Master_Portfolio'!K6 | I6: ='01_Master_Portfolio'!L6
A7: P03 | B7: mcp-sync | C7: ='01_Master_Portfolio'!F7 | D7: ='01_Master_Portfolio'!G7 | E7: ='01_Master_Portfolio'!H7 | F7: ='01_Master_Portfolio'!I7 | G7: ='01_Master_Portfolio'!J7 | H7: ='01_Master_Portfolio'!K7 | I7: ='01_Master_Portfolio'!L7
A8: P04 | B8: secret-guard | C8: ='01_Master_Portfolio'!F8 | D8: ='01_Master_Portfolio'!G8 | E8: ='01_Master_Portfolio'!H8 | F8: ='01_Master_Portfolio'!I8 | G8: ='01_Master_Portfolio'!J8 | H8: ='01_Master_Portfolio'!K8 | I8: ='01_Master_Portfolio'!L8
A9: P05 | B9: llm-spend | C9: ='01_Master_Portfolio'!F9 | D9: ='01_Master_Portfolio'!G9 | E9: ='01_Master_Portfolio'!H9 | F9: ='01_Master_Portfolio'!I9 | G9: ='01_Master_Portfolio'!J9 | H9: ='01_Master_Portfolio'!K9 | I9: ='01_Master_Portfolio'!L9
A10: P06 | B10: skill-sync | C10: ='01_Master_Portfolio'!F10 | D10: ='01_Master_Portfolio'!G10 | E10: ='01_Master_Portfolio'!H10 | F10: ='01_Master_Portfolio'!I10 | G10: ='01_Master_Portfolio'!J10 | H10: ='01_Master_Portfolio'!K10 | I10: ='01_Master_Portfolio'!L10
A11: P07 | B11: shadow-AI | C11: ='01_Master_Portfolio'!F11 | D11: ='01_Master_Portfolio'!G11 | E11: ='01_Master_Portfolio'!H11 | F11: ='01_Master_Portfolio'!I11 | G11: ='01_Master_Portfolio'!J11 | H11: ='01_Master_Portfolio'!K11 | I11: ='01_Master_Portfolio'!L11
A12: P08 | B12: eval-harness | C12: ='01_Master_Portfolio'!F12 | D12: ='01_Master_Portfolio'!G12 | E12: ='01_Master_Portfolio'!H12 | F12: ='01_Master_Portfolio'!I12 | G12: ='01_Master_Portfolio'!J12 | H12: ='01_Master_Portfolio'!K12 | I12: ='01_Master_Portfolio'!L12
A13: P09 | B13: auth-anomaly-radar | C13: ='01_Master_Portfolio'!F13 | D13: ='01_Master_Portfolio'!G13 | E13: ='01_Master_Portfolio'!H13 | F13: ='01_Master_Portfolio'!I13 | G13: ='01_Master_Portfolio'!J13 | H13: ='01_Master_Portfolio'!K13 | I13: ='01_Master_Portfolio'!L13
A14: P10 | B14: fraud-signal-kit | C14: ='01_Master_Portfolio'!F14 | D14: ='01_Master_Portfolio'!G14 | E14: ='01_Master_Portfolio'!H14 | F14: ='01_Master_Portfolio'!I14 | G14: ='01_Master_Portfolio'!J14 | H14: ='01_Master_Portfolio'!K14 | I14: ='01_Master_Portfolio'!L14
A15: P11 | B15: cloud-waste-radar | C15: ='01_Master_Portfolio'!F15 | D15: ='01_Master_Portfolio'!G15 | E15: ='01_Master_Portfolio'!H15 | F15: ='01_Master_Portfolio'!I15 | G15: ='01_Master_Portfolio'!J15 | H15: ='01_Master_Portfolio'!K15 | I15: ='01_Master_Portfolio'!L15
A16: P12 | B16: dev-onboard-os | C16: ='01_Master_Portfolio'!F16 | D16: ='01_Master_Portfolio'!G16 | E16: ='01_Master_Portfolio'!H16 | F16: ='01_Master_Portfolio'!I16 | G16: ='01_Master_Portfolio'!J16 | H16: ='01_Master_Portfolio'!K16 | I16: ='01_Master_Portfolio'!L16
... A36: P32 | B36: pr-triage | C36: ='01_Master_Portfolio'!F36 | D36: ='01_Master_Portfolio'!G36 | E36: ='01_Master_Portfolio'!H36 | F36: ='01_Master_Portfolio'!I36 | G36: ='01_Master_Portfolio'!J36 | H36: ='01_Master_Portfolio'!K36 | I36: ='01_Master_Portfolio'!L36
A38: Tip: Sort by TOTAL descending in Excel (Data → Sort) or filter Priority=NOW.
A40: Pipeline counts
A41: NOW | B41: =COUNTIF(I5:I36,"NOW")
A42: NEXT | B42: =COUNTIF(I5:I36,"NEXT")
A43: LATER | B43: =COUNTIF(I5:I36,"LATER")
A44: PARK | B44: =COUNTIF(I5:I36,"PARK")

Sheet 06_Pipeline
A1: Delivery Pipeline by Priority Band
A2: Phases populated from Master scores at generation time (static snapshot of assignment). Re-run generator after major score changes, or sort Master by Priority.
A4: NOW — Ship / double-down (next 30–60 days)
A5: ID | B5: Name | C5: TOTAL | D5: Category | E5: Stage | F5: Repo | G5: Primary action
A6: P01 | B6: instruct-sync | C6: 23 | D6: AI Tooling | E6: Shipped / iterate | F6: instruct-sync | G6: Grow npm adoption; launch posts (Show HN, r/cursor); suite cross-links
A7: P29 | B7: agent-skill-scan | C7: 23 | D7: AI Tooling / Security | E7: Design / build next | F7: agent-skill-scan | G7: Build next (≈3 wks) from setup-doctor parsers; launch on ToxicSkills narrative
A8: P02 | B8: ai-setup-doctor | C8: 22 | D8: AI Tooling | E8: Shipped / iterate | F8: ai-setup-doctor | G8: Published — tighten checks; funnel from instruct-sync README
A9: P03 | B9: mcp-sync | C9: 21 | D9: AI Tooling | E9: Shipped / iterate | F9: mcp-sync | G9: Published — consolidate naming (@bhaskarauthor/mcp-sync vs mcp-config-sync); adoption
A10: P04 | B10: secret-guard | C10: 21 | D10: AI Tooling / Security | E10: Research | F10: secret-guard | G10: Fold secret checks into P29 agent-skill-scan scope
A11: P30 | B11: agent-spend-guard | C11: 21 | D11: AI Tooling / FinOps | E11: Design | F11: agent-spend-guard | G11: Design budget/kill-switch UX; 5 eng-manager interviews; build after P29
A14: NEXT — Validate & stage (60–120 days)
A15: ID | B15: Name | C15: TOTAL | D15: Category | E15: Stage | F15: Repo | G15: Primary action
A16: P05 | B16: llm-spend | C16: 19 | D16: AI Tooling / FinOps | E16: Research | F16: llm-spend | G16: Superseded for NOW by P30; revisit as broad platform LATER
A17: P06 | B17: skill-sync | C17: 18 | D17: AI Tooling | E17: Watch | F17: skill-sync | G17: LATER after instruct/mcp patterns proven
A18: P08 | B18: eval-harness | C18: 18 | D18: AI Tooling | E18: Research | F18: eval-harness | G18: NEXT if design partner; else watch
A19: P15 | B19: wa-ops-desk | C19: 18 | D19: India SMB / WhatsApp Ops | E19: Research | F19: wa-ops-desk | G19: Pick vertical; Meta BSP sandbox; 10 SMB interviews
A20: P17 | B20: appt-book-india | C20: 18 | D20: India SMB / Appointments | E20: Research | F20: appt-book-india | G20: Salon/tutor interviews; WA reminder prototype
A21: P32 | B21: pr-triage | C21: 18 | D21: Dev Productivity / Quality | E21: Watch | F21: pr-triage | G21: Watch quarterly; build only if P29/P30 traction frees capacity
A22: P09 | B22: auth-anomaly-radar | C22: 17 | D22: Security / Identity / Fraud | E22: Research | F22: auth-anomaly-radar | G22: LATER; needs trust + data
A23: P11 | B23: cloud-waste-radar | C23: 17 | D23: Cloud FinOps | E23: Research | F23: cloud-waste-radar | G23: LATER unless clear niche
A24: P13 | B24: sbom-lite | C24: 17 | D24: Security / Supply Chain | E24: Research | F24: sbom-lite | G24: LATER OSS brand play
A25: P07 | B25: shadow-AI | C25: 16 | D25: AI Tooling / Security / GRC | E25: Research | F25: shadow-ai | G25: PARK for solo; partner or later
A26: P16 | B26: gst-ops-copilot | C26: 16 | D26: India SMB / Fintech | E26: Watch | F26: gst-ops-copilot | G26: LATER/domain partner
A27: P18 | B27: clinic-admin-lite | C27: 16 | D27: India SMB / Health Ops | E27: Research | F27: clinic-admin-lite | G27: LATER after appt-book learns domain
... A30: P31 | B30: indic-voice-flow | C30: 16 | D30: Consumer AI / Voice | E30: Research | F30: indic-voice-flow | G30: Validate Hinglish ASR quality + ₹ WTP; needs cofounder/dedicated cycle
A33: LATER — Backlog after NOW/NEXT capacity
A34: ID | B34: Name | C34: TOTAL | D34: Category | E34: Stage | F34: Repo | G34: Primary action
A35: P10 | B35: fraud-signal-kit | C35: 15 | D35: Security / Identity / Fraud | E35: Watch | F35: fraud-signal-kit | G35: PARK solo without partners
A36: P12 | B36: dev-onboard-os | C36: 15 | D36: Dev Productivity | E36: Watch | F36: dev-onboard-os | G36: Tie to setup-doctor for AI-era wedge later
A37: P14 | B37: grc-evidence-autopilot | C37: 15 | D37: Compliance / GRC | E37: Watch | F37: grc-evidence-autopilot | G37: PARK unless India DPDP-specific wedge
A38: P19 | B38: learn-loop | C38: 15 | D38: Education | E38: Watch | F38: learn-loop | G38: PARK unless passion domain
A39: P21 | B39: data-quality-guard | C39: 15 | D39: Data Quality | E39: Watch | F39: data-quality-guard | G39: PARK unless unique AI-data angle
A40: P24 | B40: creator-ops | C40: 15 | D40: Creator Ops | E40: Watch | F40: creator-ops | G40: LATER
A41: P27 | B41: focus-forge | C41: 15 | D41: Focus / Productivity Apps | E41: Watch | F41: focus-forge | G41: PARK
A42: P20 | B42: cyber-smb-shield | C42: 13 | D42: Cyber / SMB | E42: Watch | F42: cyber-smb-shield | G42: PARK without security partner
A43: P22 | B43: care-companion | C43: 13 | D43: Consumer Care | E43: Watch | F43: care-companion | G43: PARK consumer
A44: P25 | B44: climate-ops-meter | C44: 13 | D44: Climate / ESG | E44: Watch | F44: climate-ops-meter | G44: PARK without domain partner
A45: P26 | B45: supply-chain-visibility-lite | C45: 12 | D45: Supply Chain | E45: Watch | F45: sc-visibility-lite | G45: PARK
A48: PARK — Watchlist — revisit quarterly
A49: ID | B49: Name | C49: TOTAL | D49: Category | E49: Stage | F49: Repo | G49: Primary action
...

Sheet 07_Market_Context
A1: Market Context (Directional)
A2: Macro notes for portfolio strategy. Figures are directional mid-decade class estimates for brainstorming—not audited financial advice. Validate with primary sources before investor materials.
A4: Theme | B4: Directional figure | C4: Implication for portfolio | D4: Related IDs | E4: Source / note class | F4: Confidence
A5: AI agents / agent platforms | B5: ~$7–11B market mid-decade class; high CAGR ~45% class in bullish analyst ranges | C5: Prioritize AI-native tooling with PLG (CLI/npx) while category is forming | D5: P01–P08 | E5: Industry analyst ranges (e.g. agent/AI software market notes 2024–26); treat as order-of-magnitude | F5: Medium
A6: India digital economy / DX | B6: India DX ~$124–144B class for 2025–26 windows in public industry estimates; SME high CAGR | C6: India SMB WhatsApp/GST/appointments/clinic track is strategic, not side quest | D6: P15–P18, P16 | E6: Industry/NASSCOM-class digital economy commentary; range compressed for planning | F6: Medium
A7: Global SaaS | B7: SaaS still hundreds of $B TAM class; SME adoption continues despite efficiency era | C7: Seat/MRR models remain valid; need sharp ICP and low CAC | D7: P05, P11, P14, P21 | E7: Public SaaS market sizing consensus (broad) | F7: Medium
A8: Cloud waste / FinOps | B8: ~30% cloud spend waste class repeatedly cited in FinOps/Flexera-style surveys | C8: Cloud waste radar viable but crowded—need niche or automation wedge | D8: P11, P05 | E8: Flexera State of the Cloud-class surveys (historical ~30% waste narrative) | F8: Medium
A9: AI cybersecurity / managed services | B9: Large and growing; AI expands both attack surface and defense tooling | C9: Shadow-AI, secret-guard, cyber-SMB are real but sales/liability heavy | D9: P04, P07, P20, P09 | E9: Cybersecurity market reports (AI security subsegment growing faster than overall) | F9: Medium
A10: MCP & multi-agent coding | B10: Rapid ecosystem growth; standard still evolving (2024–2026) | C10: instruct-sync / mcp-sync / setup-doctor ride open standards + multi-vendor pain | D10: P01–P04, P06 | E10: Primary: MCP adoption in Cursor/VS Code/Claude ecosystems; GitHub discussions | F10: High (qualitative)
A11: Open source distribution | B11: npx/npm cold-start remains elite PLG for developer tools | C11: Bias portfolio toward OSS CLI NOW products with optional cloud later | D11: P01, P02, P03, P04, P08, P13, P28 | E11: Empirical: successful DX CLIs (eslint, prettier, supabase CLI patterns) | F11: High
A12: India WhatsApp commerce / ops | B12: WhatsApp is default business OS for huge SMB base; Cloud API monetizable | C12: wa-ops-desk + appt-book are GTM-native for Bharat SMB | D12: P15, P17, P18 | E12: Meta WhatsApp Business / India SMB digitization narratives | F12: Medium-High
A13: Compliance / GRC automation | B13: SOC2/ISO tooling multi-player market; India DPDP creates local angle | C13: Avoid pure Vanta clone; consider DPDP or AI-evidence niche only | D13: P14, P07 | E13: Category defined by Vanta/Drata/Sprinto success | F13: High (category), Low (our wedge)
A14: Creator & consumer apps | B14: Large attention markets; brutal retention and CAC | C14: Keep focus-forge, care-companion, creator-ops as PARK unless passion leverage | D14: P22–P24, P27 | E14: Consumer app economics (general) | F14: High
A15: Agent supply-chain security | B15: 36.8% of ~4k marketplace skills flawed, 1,467 malicious payloads (Snyk ToxicSkills); 71% of MCP servers graded F; 29% of orgs prepared | C15: agent-skill-scan (P29) is the highest-conviction new NOW; absorbs secret-guard scope | D15: P29, P04, P02 | E15: Snyk ToxicSkills study Feb 2026; MCP server audit 2026; incident reporting | F15: High
... A17: Paid consumer voice AI | B17: Wispr Flow ~$10M ARR, $700M valuation, $315M raised — English-first | C17: Hinglish/Indic dictation (P31) is the underserved adjacent; don't fight Wispr in English | D17: P31 | E17: Public funding/revenue reporting 2025–26 | F17: Medium-High
A19: Disclaimer
A20: Numbers are planning ranges for brainstorming alignment, not forecasts. Re-source from Gartner/IDC/NASSCOM/Flexera/primary filings before external use. Last portfolio refresh: 2026-07-11.

Sheet 08_Research_Log
A1: Research Log
A2: Append-only style log. Yellow/blue = editable fields for new entries.
A4: Date | B4: Opportunity ID | C4: Type | D4: Summary | E4: Source | F4: Impact on scores? | G4: Follow-up
A5: 2026-07-09 | B5: P01 | C5: Product | D5: instruct-sync public beta on npm as ai-instruct-sync; multi-agent rules sync working | E5: Local repo / npm beta | F5: Confirmed high ship+dist scores | G5: Show HN + retention metrics
A6: 2026-07-09 | B6: P02 | C6: Product | D6: ai-setup-doctor scaffolded build-green with fixtures for MCP/secrets/drift | E6: Local repo ai-setup-doctor/ | F6: Supports NOW priority | G6: npm publish + README funnel from instruct-sync
A7: 2026-07-09 | B7: PORTFOLIO | C7: Meta | D7: Initial 28-opportunity portfolio scored; AI CLI cluster prioritized | E7: Brainstorm + workspace roadmap | F7: Baseline scores set | G7: Re-score after 5 user interviews per NOW item
A8: 2026-07-09 | B8: P03 | C8: Market | D8: MCP multi-client config drift remains open problem; sister tool to instruct-sync justified | E8: Ecosystem observation / roadmap | F8: NEXT candidate | G8: Enumerate client MCP paths
A9: 2026-07-09 | B9: P15 | C9: Market | D9: India SMB WhatsApp ops remains high burn; competitive BSP landscape noted | E9: Market context notes | F9: Burn high, moat low | G9: Vertical selection interviews
A10: 2026-07-09 | B10: P11 | C10: Market | D10: Cloud waste ~30% class from FinOps surveys—category real but crowded | E10: Flexera-class survey narrative | F10: Moat scored low | G10: Only pursue with niche wedge
A11: 2026-07-09 | B11: MACRO | C11: Market | D11: AI agents ~$7–11B mid-decade / ~45% CAGR class directional; India DX ~$124–144B class | E11: Industry estimate ranges (directional) | F11: Supports AI tooling + India SMB dual track | G11: Attach primary sources when externalizing
A12: 2026-07-11 | B12: P02 | C12: Product | D12: Verified published on npm: ai-setup-doctor@0.1.0-beta.0 (latest+beta) | E12: npm registry check | F12: Status → Published beta; stage → Shipped | G12: Launch posts; funnel from instruct-sync README
A13: 2026-07-11 | B13: P03 | C13: Product | D13: Verified published on npm: @bhaskarauthor/mcp-sync@0.2.0 + alias mcp-config-sync@0.2.0 | E13: npm registry check | F13: Status → Published; ship 4→5 (TOTAL 21) | G13: Consolidate package naming; adoption metrics
A14: 2026-07-11 | B14: P29 | C14: Market | D14: Agent skills supply chain burning: ToxicSkills 1,467 malicious payloads, 36.8% flawed; 71% MCP servers grade F — added agent-skill-scan (TOTAL 23, NOW) | E14: Snyk ToxicSkills; MCP audit 2026 | F14: New NOW item; absorbs P04 scope | G14: Injection heuristic corpus test; build ≈3 wks
A15: 2026-07-11 | B15: P30 | C15: Market | D15: Token bill crisis (teams 3x over 2026 budgets by April; Uber, Microsoft anecdotes) — added agent-spend-guard budgets/kill-switch (TOTAL 21, NOW) | E15: TechCrunch Jun 2026; FinOps Foundation | F15: New NOW item; supersedes P05 for NOW | G15: Eng-manager WTP interviews; wrapper vs proxy
... A17: 2026-07-11 | B17: PORTFOLIO | C17: Meta | D17: Added Visibility marker (OPEN-CORE vs PRIVATE-PAID) + Paid layer column across all 32 items; hygiene-suite strategic line adopted (P01→P03→P02→P29→P30) | E17: Portfolio review session | F17: Structure change; no re-scores except P03 ship | G17: Re-score after launch-week signals
